2022-02-23 21:11:34,185 - LinearAgent - INFO - party is initialized
2022-02-23 21:11:34,222 - LinearAgent - CRITICAL - Failed to handle info
Traceback (most recent call last):
  File "/Users/billtonhoang/Documents/CollaborativeAI/src/negotiating_agent/test_agent/TU-Delft-Collaborative-AI-Negotiation/agents/time_dependent_agent/time_dependent_agent.py", line 122, in notifyChange
    self._profileint = ProfileConnectionFactory.create(
  File "/Users/billtonhoang/opt/anaconda3/lib/python3.8/site-packages/geniusweb/profileconnection/ProfileConnectionFactory.py", line 30, in create
    return FileProfileConnector(uri.getPath());
  File "/Users/billtonhoang/opt/anaconda3/lib/python3.8/site-packages/geniusweb/profileconnection/FileProfileConnector.py", line 22, in __init__
    serialized = Path(filename).read_text("utf-8")
  File "/Users/billtonhoang/opt/anaconda3/lib/python3.8/pathlib.py", line 1235, in read_text
    with self.open(mode='r', encoding=encoding, errors=errors) as f:
  File "/Users/billtonhoang/opt/anaconda3/lib/python3.8/pathlib.py", line 1221, in open
    return io.open(self, mode, buffering, encoding, errors, newline,
  File "/Users/billtonhoang/opt/anaconda3/lib/python3.8/pathlib.py", line 1077, in _opener
    return self._accessor.open(self, flags, mode)
FileNotFoundError: [Errno 2] No such file or directory: 'domains/domain00/profileA.json'
Stack (most recent call last):
  File "/Users/billtonhoang/.vscode/extensions/ms-python.python-2021.8.1159798656/pythonFiles/lib/python/debugpy/_vendored/pydevd/_pydev_bundle/pydev_monkey.py", line 1054, in __call__
    ret = self.original_func(*self.args, **self.kwargs)
  File "/Users/billtonhoang/opt/anaconda3/lib/python3.8/threading.py", line 890, in _bootstrap
    self._bootstrap_inner()
  File "/Users/billtonhoang/opt/anaconda3/lib/python3.8/threading.py", line 932, in _bootstrap_inner
    self.run()
  File "/Users/billtonhoang/opt/anaconda3/lib/python3.8/site-packages/geniusweb/simplerunner/BasicConnection.py", line 101, in run
    this._handler.notifyChange(mess.get())
  File "/Users/billtonhoang/opt/anaconda3/lib/python3.8/site-packages/geniusweb/simplerunner/ClassPathConnectionFactory.py", line 92, in notifyChange
    this._party2protocol.notifyListeners(data)
  File "/Users/billtonhoang/opt/anaconda3/lib/python3.8/site-packages/geniusweb/simplerunner/BasicConnection.py", line 168, in notifyListeners
    l.notifyChange(data)
  File "/Users/billtonhoang/Documents/CollaborativeAI/src/negotiating_agent/test_agent/TU-Delft-Collaborative-AI-Negotiation/agents/time_dependent_agent/time_dependent_agent.py", line 143, in notifyChange
    self.getReporter().log(logging.CRITICAL, "Failed to handle info", ex)
2022-02-23 21:11:34,223 - LinearAgent - CRITICAL - Failed to handle info
Traceback (most recent call last):
  File "/Users/billtonhoang/Documents/CollaborativeAI/src/negotiating_agent/test_agent/TU-Delft-Collaborative-AI-Negotiation/agents/time_dependent_agent/time_dependent_agent.py", line 132, in notifyChange
    self._myTurn()
  File "/Users/billtonhoang/Documents/CollaborativeAI/src/negotiating_agent/test_agent/TU-Delft-Collaborative-AI-Negotiation/agents/time_dependent_agent/time_dependent_agent.py", line 208, in _myTurn
    self._updateUtilSpace()
  File "/Users/billtonhoang/Documents/CollaborativeAI/src/negotiating_agent/test_agent/TU-Delft-Collaborative-AI-Negotiation/agents/time_dependent_agent/time_dependent_agent.py", line 224, in _updateUtilSpace
    newutilspace = self._profileint.getProfile()
AttributeError: 'NoneType' object has no attribute 'getProfile'
Stack (most recent call last):
  File "/Users/billtonhoang/.vscode/extensions/ms-python.python-2021.8.1159798656/pythonFiles/lib/python/debugpy/_vendored/pydevd/_pydev_bundle/pydev_monkey.py", line 1054, in __call__
    ret = self.original_func(*self.args, **self.kwargs)
  File "/Users/billtonhoang/opt/anaconda3/lib/python3.8/threading.py", line 890, in _bootstrap
    self._bootstrap_inner()
  File "/Users/billtonhoang/opt/anaconda3/lib/python3.8/threading.py", line 932, in _bootstrap_inner
    self.run()
  File "/Users/billtonhoang/opt/anaconda3/lib/python3.8/site-packages/geniusweb/simplerunner/BasicConnection.py", line 101, in run
    this._handler.notifyChange(mess.get())
  File "/Users/billtonhoang/opt/anaconda3/lib/python3.8/site-packages/geniusweb/simplerunner/ClassPathConnectionFactory.py", line 92, in notifyChange
    this._party2protocol.notifyListeners(data)
  File "/Users/billtonhoang/opt/anaconda3/lib/python3.8/site-packages/geniusweb/simplerunner/BasicConnection.py", line 168, in notifyListeners
    l.notifyChange(data)
  File "/Users/billtonhoang/Documents/CollaborativeAI/src/negotiating_agent/test_agent/TU-Delft-Collaborative-AI-Negotiation/agents/time_dependent_agent/time_dependent_agent.py", line 143, in notifyChange
    self.getReporter().log(logging.CRITICAL, "Failed to handle info", ex)
2022-02-23 21:11:35,250 - LinearAgent - INFO - Final ourcome:Finished[Agreements{}]
2022-02-23 21:11:35,250 - LinearAgent - INFO - party is terminating:
2022-02-23 21:13:20,368 - LinearAgent - INFO - party is initialized
2022-02-23 21:13:20,383 - LinearAgent - CRITICAL - Failed to handle info
Traceback (most recent call last):
  File "/Users/billtonhoang/Documents/CollaborativeAI/src/negotiating_agent/test_agent/TU-Delft-Collaborative-AI-Negotiation/agents/time_dependent_agent/time_dependent_agent.py", line 122, in notifyChange
    self._profileint = ProfileConnectionFactory.create(
  File "/Users/billtonhoang/opt/anaconda3/lib/python3.8/site-packages/geniusweb/profileconnection/ProfileConnectionFactory.py", line 30, in create
    return FileProfileConnector(uri.getPath());
  File "/Users/billtonhoang/opt/anaconda3/lib/python3.8/site-packages/geniusweb/profileconnection/FileProfileConnector.py", line 22, in __init__
    serialized = Path(filename).read_text("utf-8")
  File "/Users/billtonhoang/opt/anaconda3/lib/python3.8/pathlib.py", line 1235, in read_text
    with self.open(mode='r', encoding=encoding, errors=errors) as f:
  File "/Users/billtonhoang/opt/anaconda3/lib/python3.8/pathlib.py", line 1221, in open
    return io.open(self, mode, buffering, encoding, errors, newline,
  File "/Users/billtonhoang/opt/anaconda3/lib/python3.8/pathlib.py", line 1077, in _opener
    return self._accessor.open(self, flags, mode)
FileNotFoundError: [Errno 2] No such file or directory: 'domains/domain00/profileA.json'
Stack (most recent call last):
  File "/Users/billtonhoang/.vscode/extensions/ms-python.python-2021.8.1159798656/pythonFiles/lib/python/debugpy/_vendored/pydevd/_pydev_bundle/pydev_monkey.py", line 1054, in __call__
    ret = self.original_func(*self.args, **self.kwargs)
  File "/Users/billtonhoang/opt/anaconda3/lib/python3.8/threading.py", line 890, in _bootstrap
    self._bootstrap_inner()
  File "/Users/billtonhoang/opt/anaconda3/lib/python3.8/threading.py", line 932, in _bootstrap_inner
    self.run()
  File "/Users/billtonhoang/opt/anaconda3/lib/python3.8/site-packages/geniusweb/simplerunner/BasicConnection.py", line 101, in run
    this._handler.notifyChange(mess.get())
  File "/Users/billtonhoang/opt/anaconda3/lib/python3.8/site-packages/geniusweb/simplerunner/ClassPathConnectionFactory.py", line 92, in notifyChange
    this._party2protocol.notifyListeners(data)
  File "/Users/billtonhoang/opt/anaconda3/lib/python3.8/site-packages/geniusweb/simplerunner/BasicConnection.py", line 168, in notifyListeners
    l.notifyChange(data)
  File "/Users/billtonhoang/Documents/CollaborativeAI/src/negotiating_agent/test_agent/TU-Delft-Collaborative-AI-Negotiation/agents/time_dependent_agent/time_dependent_agent.py", line 143, in notifyChange
    self.getReporter().log(logging.CRITICAL, "Failed to handle info", ex)
2022-02-23 21:13:20,384 - LinearAgent - CRITICAL - Failed to handle info
Traceback (most recent call last):
  File "/Users/billtonhoang/Documents/CollaborativeAI/src/negotiating_agent/test_agent/TU-Delft-Collaborative-AI-Negotiation/agents/time_dependent_agent/time_dependent_agent.py", line 132, in notifyChange
    self._myTurn()
  File "/Users/billtonhoang/Documents/CollaborativeAI/src/negotiating_agent/test_agent/TU-Delft-Collaborative-AI-Negotiation/agents/time_dependent_agent/time_dependent_agent.py", line 208, in _myTurn
    self._updateUtilSpace()
  File "/Users/billtonhoang/Documents/CollaborativeAI/src/negotiating_agent/test_agent/TU-Delft-Collaborative-AI-Negotiation/agents/time_dependent_agent/time_dependent_agent.py", line 224, in _updateUtilSpace
    newutilspace = self._profileint.getProfile()
AttributeError: 'NoneType' object has no attribute 'getProfile'
Stack (most recent call last):
  File "/Users/billtonhoang/.vscode/extensions/ms-python.python-2021.8.1159798656/pythonFiles/lib/python/debugpy/_vendored/pydevd/_pydev_bundle/pydev_monkey.py", line 1054, in __call__
    ret = self.original_func(*self.args, **self.kwargs)
  File "/Users/billtonhoang/opt/anaconda3/lib/python3.8/threading.py", line 890, in _bootstrap
    self._bootstrap_inner()
  File "/Users/billtonhoang/opt/anaconda3/lib/python3.8/threading.py", line 932, in _bootstrap_inner
    self.run()
  File "/Users/billtonhoang/opt/anaconda3/lib/python3.8/site-packages/geniusweb/simplerunner/BasicConnection.py", line 101, in run
    this._handler.notifyChange(mess.get())
  File "/Users/billtonhoang/opt/anaconda3/lib/python3.8/site-packages/geniusweb/simplerunner/ClassPathConnectionFactory.py", line 92, in notifyChange
    this._party2protocol.notifyListeners(data)
  File "/Users/billtonhoang/opt/anaconda3/lib/python3.8/site-packages/geniusweb/simplerunner/BasicConnection.py", line 168, in notifyListeners
    l.notifyChange(data)
  File "/Users/billtonhoang/Documents/CollaborativeAI/src/negotiating_agent/test_agent/TU-Delft-Collaborative-AI-Negotiation/agents/time_dependent_agent/time_dependent_agent.py", line 143, in notifyChange
    self.getReporter().log(logging.CRITICAL, "Failed to handle info", ex)
2022-02-23 21:13:21,407 - LinearAgent - INFO - Final ourcome:Finished[Agreements{}]
2022-02-23 21:13:21,408 - LinearAgent - INFO - party is terminating:
2022-02-23 21:13:51,819 - LinearAgent - INFO - party is initialized
2022-02-23 21:13:51,834 - LinearAgent - CRITICAL - Failed to handle info
Traceback (most recent call last):
  File "/Users/billtonhoang/Documents/CollaborativeAI/src/negotiating_agent/test_agent/TU-Delft-Collaborative-AI-Negotiation/agents/time_dependent_agent/time_dependent_agent.py", line 122, in notifyChange
    self._profileint = ProfileConnectionFactory.create(
  File "/Users/billtonhoang/opt/anaconda3/lib/python3.8/site-packages/geniusweb/profileconnection/ProfileConnectionFactory.py", line 30, in create
    return FileProfileConnector(uri.getPath());
  File "/Users/billtonhoang/opt/anaconda3/lib/python3.8/site-packages/geniusweb/profileconnection/FileProfileConnector.py", line 22, in __init__
    serialized = Path(filename).read_text("utf-8")
  File "/Users/billtonhoang/opt/anaconda3/lib/python3.8/pathlib.py", line 1235, in read_text
    with self.open(mode='r', encoding=encoding, errors=errors) as f:
  File "/Users/billtonhoang/opt/anaconda3/lib/python3.8/pathlib.py", line 1221, in open
    return io.open(self, mode, buffering, encoding, errors, newline,
  File "/Users/billtonhoang/opt/anaconda3/lib/python3.8/pathlib.py", line 1077, in _opener
    return self._accessor.open(self, flags, mode)
FileNotFoundError: [Errno 2] No such file or directory: 'domains/domain00/profileA.json'
Stack (most recent call last):
  File "/Users/billtonhoang/.vscode/extensions/ms-python.python-2021.8.1159798656/pythonFiles/lib/python/debugpy/_vendored/pydevd/_pydev_bundle/pydev_monkey.py", line 1054, in __call__
    ret = self.original_func(*self.args, **self.kwargs)
  File "/Users/billtonhoang/opt/anaconda3/lib/python3.8/threading.py", line 890, in _bootstrap
    self._bootstrap_inner()
  File "/Users/billtonhoang/opt/anaconda3/lib/python3.8/threading.py", line 932, in _bootstrap_inner
    self.run()
  File "/Users/billtonhoang/opt/anaconda3/lib/python3.8/site-packages/geniusweb/simplerunner/BasicConnection.py", line 101, in run
    this._handler.notifyChange(mess.get())
  File "/Users/billtonhoang/opt/anaconda3/lib/python3.8/site-packages/geniusweb/simplerunner/ClassPathConnectionFactory.py", line 92, in notifyChange
    this._party2protocol.notifyListeners(data)
  File "/Users/billtonhoang/opt/anaconda3/lib/python3.8/site-packages/geniusweb/simplerunner/BasicConnection.py", line 168, in notifyListeners
    l.notifyChange(data)
  File "/Users/billtonhoang/Documents/CollaborativeAI/src/negotiating_agent/test_agent/TU-Delft-Collaborative-AI-Negotiation/agents/time_dependent_agent/time_dependent_agent.py", line 143, in notifyChange
    self.getReporter().log(logging.CRITICAL, "Failed to handle info", ex)
2022-02-23 21:13:51,836 - LinearAgent - CRITICAL - Failed to handle info
Traceback (most recent call last):
  File "/Users/billtonhoang/Documents/CollaborativeAI/src/negotiating_agent/test_agent/TU-Delft-Collaborative-AI-Negotiation/agents/time_dependent_agent/time_dependent_agent.py", line 132, in notifyChange
    self._myTurn()
  File "/Users/billtonhoang/Documents/CollaborativeAI/src/negotiating_agent/test_agent/TU-Delft-Collaborative-AI-Negotiation/agents/time_dependent_agent/time_dependent_agent.py", line 208, in _myTurn
    self._updateUtilSpace()
  File "/Users/billtonhoang/Documents/CollaborativeAI/src/negotiating_agent/test_agent/TU-Delft-Collaborative-AI-Negotiation/agents/time_dependent_agent/time_dependent_agent.py", line 224, in _updateUtilSpace
    newutilspace = self._profileint.getProfile()
AttributeError: 'NoneType' object has no attribute 'getProfile'
Stack (most recent call last):
  File "/Users/billtonhoang/.vscode/extensions/ms-python.python-2021.8.1159798656/pythonFiles/lib/python/debugpy/_vendored/pydevd/_pydev_bundle/pydev_monkey.py", line 1054, in __call__
    ret = self.original_func(*self.args, **self.kwargs)
  File "/Users/billtonhoang/opt/anaconda3/lib/python3.8/threading.py", line 890, in _bootstrap
    self._bootstrap_inner()
  File "/Users/billtonhoang/opt/anaconda3/lib/python3.8/threading.py", line 932, in _bootstrap_inner
    self.run()
  File "/Users/billtonhoang/opt/anaconda3/lib/python3.8/site-packages/geniusweb/simplerunner/BasicConnection.py", line 101, in run
    this._handler.notifyChange(mess.get())
  File "/Users/billtonhoang/opt/anaconda3/lib/python3.8/site-packages/geniusweb/simplerunner/ClassPathConnectionFactory.py", line 92, in notifyChange
    this._party2protocol.notifyListeners(data)
  File "/Users/billtonhoang/opt/anaconda3/lib/python3.8/site-packages/geniusweb/simplerunner/BasicConnection.py", line 168, in notifyListeners
    l.notifyChange(data)
  File "/Users/billtonhoang/Documents/CollaborativeAI/src/negotiating_agent/test_agent/TU-Delft-Collaborative-AI-Negotiation/agents/time_dependent_agent/time_dependent_agent.py", line 143, in notifyChange
    self.getReporter().log(logging.CRITICAL, "Failed to handle info", ex)
2022-02-23 21:13:52,864 - LinearAgent - INFO - Final ourcome:Finished[Agreements{}]
2022-02-23 21:13:52,865 - LinearAgent - INFO - party is terminating:
2022-02-23 21:21:49,065 - LinearAgent - INFO - party is initialized
2022-02-23 21:21:49,073 - LinearAgent - CRITICAL - Failed to handle info
Traceback (most recent call last):
  File "/Users/billtonhoang/Documents/CollaborativeAI/src/negotiating_agent/test_agent/TU-Delft-Collaborative-AI-Negotiation/agents/time_dependent_agent/time_dependent_agent.py", line 122, in notifyChange
    self._profileint = ProfileConnectionFactory.create(
  File "/Users/billtonhoang/opt/anaconda3/lib/python3.8/site-packages/geniusweb/profileconnection/ProfileConnectionFactory.py", line 30, in create
    return FileProfileConnector(uri.getPath());
  File "/Users/billtonhoang/opt/anaconda3/lib/python3.8/site-packages/geniusweb/profileconnection/FileProfileConnector.py", line 22, in __init__
    serialized = Path(filename).read_text("utf-8")
  File "/Users/billtonhoang/opt/anaconda3/lib/python3.8/pathlib.py", line 1235, in read_text
    with self.open(mode='r', encoding=encoding, errors=errors) as f:
  File "/Users/billtonhoang/opt/anaconda3/lib/python3.8/pathlib.py", line 1221, in open
    return io.open(self, mode, buffering, encoding, errors, newline,
  File "/Users/billtonhoang/opt/anaconda3/lib/python3.8/pathlib.py", line 1077, in _opener
    return self._accessor.open(self, flags, mode)
FileNotFoundError: [Errno 2] No such file or directory: 'domains/domain00/profileA.json'
Stack (most recent call last):
  File "/Users/billtonhoang/opt/anaconda3/lib/python3.8/threading.py", line 890, in _bootstrap
    self._bootstrap_inner()
  File "/Users/billtonhoang/opt/anaconda3/lib/python3.8/threading.py", line 932, in _bootstrap_inner
    self.run()
  File "/Users/billtonhoang/opt/anaconda3/lib/python3.8/site-packages/geniusweb/simplerunner/BasicConnection.py", line 101, in run
    this._handler.notifyChange(mess.get())
  File "/Users/billtonhoang/opt/anaconda3/lib/python3.8/site-packages/geniusweb/simplerunner/ClassPathConnectionFactory.py", line 92, in notifyChange
    this._party2protocol.notifyListeners(data)
  File "/Users/billtonhoang/opt/anaconda3/lib/python3.8/site-packages/geniusweb/simplerunner/BasicConnection.py", line 168, in notifyListeners
    l.notifyChange(data)
  File "/Users/billtonhoang/Documents/CollaborativeAI/src/negotiating_agent/test_agent/TU-Delft-Collaborative-AI-Negotiation/agents/time_dependent_agent/time_dependent_agent.py", line 143, in notifyChange
    self.getReporter().log(logging.CRITICAL, "Failed to handle info", ex)
2022-02-23 21:21:49,073 - LinearAgent - CRITICAL - Failed to handle info
Traceback (most recent call last):
  File "/Users/billtonhoang/Documents/CollaborativeAI/src/negotiating_agent/test_agent/TU-Delft-Collaborative-AI-Negotiation/agents/time_dependent_agent/time_dependent_agent.py", line 132, in notifyChange
    self._myTurn()
  File "/Users/billtonhoang/Documents/CollaborativeAI/src/negotiating_agent/test_agent/TU-Delft-Collaborative-AI-Negotiation/agents/time_dependent_agent/time_dependent_agent.py", line 208, in _myTurn
    self._updateUtilSpace()
  File "/Users/billtonhoang/Documents/CollaborativeAI/src/negotiating_agent/test_agent/TU-Delft-Collaborative-AI-Negotiation/agents/time_dependent_agent/time_dependent_agent.py", line 224, in _updateUtilSpace
    newutilspace = self._profileint.getProfile()
AttributeError: 'NoneType' object has no attribute 'getProfile'
Stack (most recent call last):
  File "/Users/billtonhoang/opt/anaconda3/lib/python3.8/threading.py", line 890, in _bootstrap
    self._bootstrap_inner()
  File "/Users/billtonhoang/opt/anaconda3/lib/python3.8/threading.py", line 932, in _bootstrap_inner
    self.run()
  File "/Users/billtonhoang/opt/anaconda3/lib/python3.8/site-packages/geniusweb/simplerunner/BasicConnection.py", line 101, in run
    this._handler.notifyChange(mess.get())
  File "/Users/billtonhoang/opt/anaconda3/lib/python3.8/site-packages/geniusweb/simplerunner/ClassPathConnectionFactory.py", line 92, in notifyChange
    this._party2protocol.notifyListeners(data)
  File "/Users/billtonhoang/opt/anaconda3/lib/python3.8/site-packages/geniusweb/simplerunner/BasicConnection.py", line 168, in notifyListeners
    l.notifyChange(data)
  File "/Users/billtonhoang/Documents/CollaborativeAI/src/negotiating_agent/test_agent/TU-Delft-Collaborative-AI-Negotiation/agents/time_dependent_agent/time_dependent_agent.py", line 143, in notifyChange
    self.getReporter().log(logging.CRITICAL, "Failed to handle info", ex)
2022-02-23 21:21:50,098 - LinearAgent - INFO - Final ourcome:Finished[Agreements{}]
2022-02-23 21:21:50,099 - LinearAgent - INFO - party is terminating:
